<?xml version="1.0" ?>
<!-- =================================================================================== -->
<!-- |    This document was autogenerated by xacro from /home/enzo/Scrivania/ROS_RT2/ros_ws/src/ExperimentalRoboticsLab/urdf/m2wr_arm.xacro | -->
<!-- |    EDITING THIS FILE BY HAND IS NOT RECOMMENDED                                 | -->
<!-- =================================================================================== -->
<robot name="m2wr">
    <material name="black">
        <color rgba="0.0 0.0 0.0 1.0" />
    </material>
    <material name="blue">
        <color rgba="0.203125 0.23828125 0.28515625 1.0" />
    </material>
    <material name="green">
        <color rgba="0.0 0.8 0.0 1.0" />
    </material>
    <material name="grey">
        <color rgba="0.2 0.2 0.2 1.0" />
    </material>
    <material name="orange">
        <color rgba="1.0 0.423529411765 0.0392156862745 1.0" />
    </material>
    <material name="brown">
        <color rgba="0.870588235294 0.811764705882 0.764705882353 1.0" />
    </material>
    <material name="red">
        <color rgba="0.80078125 0.12890625 0.1328125 1.0" />
    </material>
    <material name="white">
        <color rgba="1.0 1.0 1.0 1.0" />
    </material>
    <gazebo reference="base_link">
        <material>Gazebo/Orange</material>
    </gazebo>
    <gazebo reference="link_left_wheel">
        <material>Gazebo/Blue</material>
    </gazebo>
    <gazebo reference="link_right_wheel">
        <material>Gazebo/Blue</material>
    </gazebo>
    <gazebo reference="arm_base_link">
        <material>Gazebo/Red</material>
    </gazebo>
    <gazebo reference="arm_link_01">
        <material>Gazebo/Red</material>
    </gazebo>
    <gazebo reference="arm_link_02">
        <material>Gazebo/Red</material>
    </gazebo>
    <gazebo reference="arm_link_03">
        <material>Gazebo/Red</material>
    </gazebo>
    <gazebo reference="arm_link_04">
        <material>Gazebo/Red</material>
    </gazebo>
    <gazebo reference="cluedo_link">
        <material>Gazebo/White</material>
    </gazebo>
    <gazebo>
        <plugin filename="libgazebo_ros_diff_drive.so" name="differential_drive_controller">
            <legacyMode>true</legacyMode>
            <alwaysOn>true</alwaysOn>
            <updateRate>20</updateRate>
            <leftJoint>joint_left_wheel</leftJoint>
            <rightJoint>joint_right_wheel</rightJoint>
            <wheelSeparation>0.64</wheelSeparation>
            <wheelDiameter>0.26</wheelDiameter>
            <torque>0.3</torque>
            <commandTopic>cmd_vel</commandTopic>
            <odometryTopic>odom</odometryTopic>
            <odometryFrame>odom</odometryFrame>
            <robotBaseFrame>base_link</robotBaseFrame>
            <rosDebugLevel>na</rosDebugLevel>
            <publishWheelTF>true</publishWheelTF>
            <publishWheelJointState>true</publishWheelJointState>
            <wheelAcceleration>0</wheelAcceleration>
            <wheelTorque>11</wheelTorque>
            <odometrySource>1</odometrySource>
            <publishTf>1</publishTf>
        </plugin>
    </gazebo>
    <gazebo>
        <plugin filename="libgazebo_ros_control.so" name="gazebo_ros_control">
            <robotNamespace>m2wr</robotNamespace>
            <robotSimType>gazebo_ros_control/DefaultRobotHWSim</robotSimType>
            <legacyModeNS>true</legacyModeNS>
        </plugin>
    </gazebo>
    <gazebo reference="laser">
        <sensor name="head_hokuyo_sensor" type="ray">
            <pose>0 0 0 0 0 0</pose>
            <visualize>false</visualize>
            <update_rate>20</update_rate>
            <ray>
                <scan>
                    <horizontal>
                        <samples>720</samples>
                        <resolution>1</resolution>
                        <min_angle>-1.570796</min_angle>
                        <max_angle>1.570796</max_angle>
                    </horizontal>
                </scan>
                <range>
                    <min>0.10</min>
                    <max>10.0</max>
                    <resolution>0.01</resolution>
                </range>
                <noise>
                    <type>gaussian</type>
                    <mean>0.0</mean>
                    <stddev>0.01</stddev>
                </noise>
            </ray>
            <plugin filename="libgazebo_ros_laser.so" name="gazebo_ros_head_hokuyo_controller">
                <topicName>m2wr/laser/scan</topicName>
                <frameName>laser</frameName>
            </plugin>
        </sensor>
    </gazebo>
    <gazebo reference="arm_joint_01">
        <provideFeedback>true</provideFeedback>
    </gazebo>
    <gazebo>
        <plugin filename="libgazebo_ros_ft_sensor.so" name="ft_sensor">
            <updateRate>100.0</updateRate>
            <topicName>ft_sensor_topic</topicName>
            <jointName>arm_joint_01</jointName>
        </plugin>
    </gazebo>
    <gazebo reference="arm_joint_02">
        <provideFeedback>true</provideFeedback>
    </gazebo>
    <gazebo>
        <plugin filename="libgazebo_ros_ft_sensor.so" name="ft_sensor">
            <updateRate>100.0</updateRate>
            <topicName>ft_sensor_topic</topicName>
            <jointName>arm_joint_02</jointName>
        </plugin>
    </gazebo>
    <gazebo reference="arm_joint_03">
        <provideFeedback>true</provideFeedback>
    </gazebo>
    <gazebo>
        <plugin filename="libgazebo_ros_ft_sensor.so" name="ft_sensor">
            <updateRate>100.0</updateRate>
            <topicName>ft_sensor_topic</topicName>
            <jointName>arm_joint_03</jointName>
        </plugin>
    </gazebo>
    <gazebo reference="arm_joint_04">
        <provideFeedback>true</provideFeedback>
    </gazebo>
    <gazebo>
        <plugin filename="libgazebo_ros_ft_sensor.so" name="ft_sensor">
            <updateRate>100.0</updateRate>
            <topicName>ft_sensor_topic</topicName>
            <jointName>arm_joint_04</jointName>
        </plugin>
    </gazebo>
    <gazebo reference="cluedo_joint">
        <provideFeedback>true</provideFeedback>
    </gazebo>
    <gazebo>
        <plugin filename="libgazebo_ros_ft_sensor.so" name="ft_sensor">
            <updateRate>100.0</updateRate>
            <topicName>ft_sensor_topic</topicName>
            <jointName>cluedo_joint</jointName>
        </plugin>
    </gazebo>
    <link name="base_link">
        <!-- pose and inertial -->
        <pose>0 0 0.1 0 0 0</pose>
        
<inertial>
            <mass value="7.5" />
            <origin rpy="0 0 0" xyz="0 0 0.12" />
            <inertia ixx="0.0395416666667" ixy="0" ixz="0" iyy="0.106208333333" iyz="0" izz="0.106208333333" />
        </inertial>

        <collision name="collision_chassis">
            <geometry>
                <box size="0.8 0.6 0.08" />
            </geometry>
        </collision>
        <visual>
            <origin rpy="0 0 0" xyz="0 0 0" />
            <geometry>
                <box size="0.8 0.6 0.08" />
            </geometry>
            <material name="blue" />
        </visual>
        <!-- caster front -->
        <collision name="caster_front_collision">
            <origin rpy=" 0 0 0" xyz="0.325 0 -0.065" />
            <geometry>
                <sphere radius="0.065" />
            </geometry>
            <surface>
                <friction>
                    <ode>
                        <mu>0</mu>
                        <mu2>0</mu2>
                        <slip1>1.0</slip1>
                        <slip2>1.0</slip2>
                    </ode>
                </friction>
            </surface>
        </collision>
        <visual name="caster_front_visual">
            <origin rpy=" 0 0 0" xyz="0.325 0 -0.065" />
            <geometry>
                <sphere radius="0.065" />
            </geometry>
        </visual>
    </link>
    <!-- Create wheels -->
    <link name="link_right_wheel">
        
<inertial>
            <mass value="0.2" />
            <origin rpy="0 1.5707 1.5707" xyz="0 0 0" />
            <inertia ixx="0.000526666666667" ixy="0" ixz="0" iyy="0.000526666666667" iyz="0" izz="0.001" />
        </inertial>

        <collision name="link_right_wheel_collision">
            <origin rpy="0 1.5707 1.5707" xyz="0 0 0" />
            <geometry>
                <cylinder length="0.04" radius="0.13" />
            </geometry>
        </collision>
        <visual name="link_right_wheel_visual">
            <origin rpy="0 1.5707 1.5707" xyz="0 0 0" />
            <geometry>
                <cylinder length="0.04" radius="0.13" />
            </geometry>
        </visual>
    </link>
    <link name="link_left_wheel">
        
<inertial>
            <mass value="0.2" />
            <origin rpy="0 1.5707 1.5707" xyz="0 0 0" />
            <inertia ixx="0.000526666666667" ixy="0" ixz="0" iyy="0.000526666666667" iyz="0" izz="0.001" />
        </inertial>

        <collision name="link_right_wheel_collision">
            <origin rpy="0 1.5707 1.5707" xyz="0 0 0" />
            <geometry>
                <cylinder length="0.04" radius="0.13" />
            </geometry>
        </collision>
        <visual name="link_left_wheel_visual">
            <origin rpy="0 1.5707 1.5707" xyz="0 0 0" />
            <geometry>
                <cylinder length="0.04" radius="0.13" />
            </geometry>
        </visual>
    </link>
    <joint name="joint_right_wheel" type="continuous">
        <origin rpy="0 0 0" xyz="-0.15 0.32 0" />
        <child link="link_right_wheel" />
        <parent link="base_link" />
        <axis rpy="0 0 0" xyz="0 1 0" />
        <limit effort="10000" velocity="1000" />
        <joint_properties damping="1.0" friction="1.0" />
    </joint>
    <joint name="joint_left_wheel" type="continuous">
        <origin rpy="0 0 0" xyz="-0.15 -0.32 0" />
        <child link="link_left_wheel" />
        <parent link="base_link" />
        <axis rpy="0 0 0" xyz="0 1 0" />
        <limit effort="10000" velocity="1000" />
        <joint_properties damping="1.0" friction="1.0" />
    </joint>
    <!-- Laser and Link Laser-->
    <link name="laser">
        
<inertial>
            <origin rpy="0 0 0" xyz="0 0 0" />
            <mass value="1" />
            <inertia ixx="0.0014583333333333334" ixy="0" ixz="0" iyy="0.0014583333333333334" iyz="0" izz="0.0012500000000000002" />
        </inertial>

        <visual>
            <origin rpy="0 0 0" xyz="0 0 0" />
            <geometry>
                <cylinder length="0.1" radius="0.05" />
            </geometry>
            <material name="white" />
        </visual>
        <collision>
            <origin rpy="0 0 0" xyz="0 0 0" />
            <geometry>
                <cylinder length="0.1" radius="0.05" />
            </geometry>
        </collision>
    </link>
    <joint name="joint_laser" type="fixed">
        <origin rpy="0 0 0" xyz="0.3 0 0.05" />
        <parent link="base_link" />
        <child link="laser" />
    </joint>
    <!--arm definition -->
    <link name="arm_base_link">
        
<inertial>
            <mass value="0.35" />
            <origin rpy="0 1.57 0" xyz="0 0 0.085" />
            <inertia ixx="0.0000416666667" ixy="0" ixz="0" iyy="0.0000416666667" iyz="0" izz="0.0000416666667" />
        </inertial>

        <collision>
            <origin rpy="0 1.57 0" xyz="0 0 0.088" />
            <geometry>
                <box size="0.18 0.18 0.47" />
            </geometry>
        </collision>
        <visual>
            <origin rpy="0 1.57 0" xyz="0 0 0.088" />
            <geometry>
                <box size="0.18 0.18 0.47" />
            </geometry>
            <material name="red" />
        </visual>
    </link>
    <joint name="arm_base_to_base" type="prismatic">
        <limit effort="1000.0" lower="0" upper="0.27" velocity="2" />
        <origin rpy="0 -1.57 0" xyz="0 0 0.15" />
        <parent link="base_link" />
        <child link="arm_base_link" />
    </joint>
    <link name="arm_link_01">
        
<inertial>
            <mass value="0.045" />
            <origin rpy="0 0 0" xyz="0 0 0" />
            <inertia ixx="0.000010279" ixy="0" ixz="0" iyy="0.000010279" iyz="0" izz="0.000007225" />
        </inertial>

        <collision>
            <origin rpy="0 0 0" xyz="0 0 0" />
            <geometry>
                <cylinder length="0.4" radius="0.045" />
            </geometry>
        </collision>
        <visual>
            <origin rpy="0 0 0" xyz="0 0 0" />
            <geometry>
                <cylinder length="0.4" radius="0.045" />
            </geometry>
            <material name="red" />
        </visual>
    </link>
    <joint name="arm_joint_01" type="revolute">
        <axis xyz="0 0 1" />
        <limit effort="1000.0" lower="-3.14" upper="3.14" velocity="0.5" />
        <origin rpy="0 1.57 0" xyz="0.4 0 0.1" />
        <parent link="arm_base_link" />
        <child link="arm_link_01" />
    </joint>
    <link name="arm_link_02">
        
<inertial>
            <mass value="0.025" />
            <origin rpy="0 0 0" xyz="0 0 0" />
            <inertia ixx="0.000010279" ixy="0" ixz="0" iyy="0.000010279" iyz="0" izz="0.000007225" />
        </inertial>

        <collision>
            <origin rpy="0 0 0" xyz="0 0.01 0" />
            <geometry>
                <cylinder length="0.2" radius="0.04" />
            </geometry>
        </collision>
        <visual>
            <origin rpy="0 0 0" xyz="0 0.01 0" />
            <geometry>
                <cylinder length="0.2" radius="0.04" />
            </geometry>
            <material name="red" />
        </visual>
    </link>
    <joint name="arm_joint_02" type="revolute">
        <axis xyz="0 0 1" />
        <limit effort="1000.0" lower="-1.8" upper="1.8" velocity="0.3" />
        <origin rpy="1.57 0 0" xyz="0 0 0.18" />
        <parent link="arm_link_01" />
        <child link="arm_link_02" />
    </joint>
    <link name="arm_link_03">
        
<inertial>
            <mass value="0.015" />
            <origin rpy="0 0 0" xyz="0 0 0.21" />
            <inertia ixx="0.000010279" ixy="0" ixz="0" iyy="0.000010279" iyz="0" izz="0.000007225" />
        </inertial>

        <collision>
            <origin rpy="0 0 0" xyz="0 0 0.21" />
            <geometry>
                <cylinder length="0.7" radius="0.036" />
            </geometry>
        </collision>
        <visual>
            <origin rpy="0 0 0" xyz="0 0 0.21" />
            <geometry>
                <cylinder length="0.7" radius="0.036" />
            </geometry>
            <material name="red" />
        </visual>
    </link>
    <joint name="arm_joint_03" type="revolute">
        <axis xyz="0 0 1" />
        <limit effort="1000.0" lower="-1.8" upper="1.8" velocity="0.3" />
        <origin rpy="-1.57 0 0" xyz="0 0 0" />
        <parent link="arm_link_02" />
        <child link="arm_link_03" />
    </joint>
    <link name="arm_link_04">
        
<inertial>
            <mass value="0.0125" />
            <origin rpy="0 0 0" xyz="0 0 0.04" />
            <inertia ixx="0.000010279" ixy="0" ixz="0" iyy="0.000010279" iyz="0" izz="0.000007225" />
        </inertial>

        <collision>
            <origin rpy="0 0 1.57" xyz="0 0 0.04" />
            <geometry>
                <box size="0.034 0.2 0.08" />
            </geometry>
        </collision>
        <visual>
            <origin rpy="0 0 1.57" xyz="0 0 0.04" />
            <geometry>
                <box size="0.034 0.2 0.08" />
            </geometry>
            <material name="red" />
        </visual>
    </link>
    <joint name="arm_joint_04" type="revolute">
        <axis xyz="1 0 0" />
        <limit effort="1000.0" lower="-1.8" upper="1.8" velocity="0.75" />
        <origin rpy="0 0 0" xyz="0 0 0.57" />
        <parent link="arm_link_03" />
        <child link="arm_link_04" />
    </joint>
    <link name="cluedo_link">
        
<inertial>
            <mass value="0.0075" />
            <origin rpy="0 0 0" xyz="0 0 0" />
            <inertia ixx="0.000010279" ixy="0" ixz="0" iyy="0.000010279" iyz="0" izz="0.000007225" />
        </inertial>

        <collision>
            <origin rpy="0 3.1415 -1.57" xyz="0 0.048 0.04" />
            <geometry>
                <box size="0.06 0.02 0.08" />
            </geometry>
        </collision>
        <visual>
            <origin rpy="0 3.1415 -1.57" xyz="0 0.048 0.04" />
            <geometry>
                <box size="0.06 0.02 0.08" />
            </geometry>
            <material name="white" />
        </visual>
    </link>
    <joint name="cluedo_joint" type="prismatic">
        <axis xyz="1 0 0" />
        <limit effort="1000.0" lower="-0.04" upper="0.035" velocity="6.5" />
        <origin rpy="0 0 0" xyz="0 0 0" />
        <parent link="arm_link_04" />
        <child link="cluedo_link" />
    </joint>
    
<transmission name="arm_joint_base_trans">
        <type>transmission_interface/SimpleTransmission</type>
        <joint name="arm_base_to_base">
            <hardwareInterface>hardware_interface/EffortJointInterface</hardwareInterface>
        </joint>
        <actuator name="motor0">
            <hardwareInterface>hardware_interface/EffortJointInterface</hardwareInterface>
            <mechanicalInterface>1</mechanicalInterface>
        </actuator>
    </transmission>
    <transmission name="arm_joint_01_trans">
        <type>transmission_interface/SimpleTransmission</type>
        <joint name="arm_joint_01">
            <hardwareInterface>hardware_interface/EffortJointInterface</hardwareInterface>
        </joint>
        <actuator name="motor1">
            <hardwareInterface>hardware_interface/EffortJointInterface</hardwareInterface>
            <mechanicalInterface>1</mechanicalInterface>
        </actuator>
    </transmission>
    <transmission name="arm_joint_02_trans">
        <type>transmission_interface/SimpleTransmission</type>
        <joint name="arm_joint_02">
            <hardwareInterface>hardware_interface/EffortJointInterface</hardwareInterface>
        </joint>
        <actuator name="motor2">
            <hardwareInterface>hardware_interface/EffortJointInterface</hardwareInterface>
            <mechanicalInterface>1</mechanicalInterface>
        </actuator>
    </transmission>
    <transmission name="arm_joint_03_trans">
        <type>transmission_interface/SimpleTransmission</type>
        <joint name="arm_joint_03">
            <hardwareInterface>hardware_interface/EffortJointInterface</hardwareInterface>
        </joint>
        <actuator name="motor3">
            <hardwareInterface>hardware_interface/EffortJointInterface</hardwareInterface>
            <mechanicalInterface>1</mechanicalInterface>
        </actuator>
    </transmission>
    <transmission name="arm_joint_04_trans">
        <type>transmission_interface/SimpleTransmission</type>
        <joint name="arm_joint_04">
            <hardwareInterface>hardware_interface/EffortJointInterface</hardwareInterface>
        </joint>
        <actuator name="motor4">
            <hardwareInterface>hardware_interface/EffortJointInterface</hardwareInterface>
            <mechanicalInterface>1</mechanicalInterface>
        </actuator>
    </transmission>
    <transmission name="cluedo_joint_trans">
        <type>transmission_interface/SimpleTransmission</type>
        <joint name="cluedo_joint">
            <hardwareInterface>hardware_interface/EffortJointInterface</hardwareInterface>
        </joint>
        <actuator name="motor5">
            <hardwareInterface>hardware_interface/EffortJointInterface</hardwareInterface>
            <mechanicalInterface>1</mechanicalInterface>
        </actuator>
    </transmission>
    <transmission name="trans_joint_right_wheel">
        <type>transmission_interface/SimpleTransmission</type>
        <joint name="joint_right_wheel">
            <hardwareInterface>hardware_interface/EffortJointInterface</hardwareInterface>
        </joint>
        <actuator name="joint_right_wheel_motor">
            <hardwareInterface>hardware_interface/EffortJointInterface</hardwareInterface>
            <mechanicalReduction>1</mechanicalReduction>
        </actuator>
    </transmission>
    <transmission name="trans_joint_left_wheel">
        <type>transmission_interface/SimpleTransmission</type>
        <joint name="joint_left_wheel">
            <hardwareInterface>hardware_interface/EffortJointInterface</hardwareInterface>
        </joint>
        <actuator name="joint_left_wheel_motor">
            <hardwareInterface>hardware_interface/EffortJointInterface</hardwareInterface>
            <mechanicalReduction>1</mechanicalReduction>
        </actuator>
    </transmission>
    <transmission name="trans_arm_base_to_base">
        <type>transmission_interface/SimpleTransmission</type>
        <joint name="arm_base_to_base">
            <hardwareInterface>hardware_interface/EffortJointInterface</hardwareInterface>
        </joint>
        <actuator name="arm_base_to_base_motor">
            <hardwareInterface>hardware_interface/EffortJointInterface</hardwareInterface>
            <mechanicalReduction>1</mechanicalReduction>
        </actuator>
    </transmission>
    <transmission name="trans_arm_joint_01">
        <type>transmission_interface/SimpleTransmission</type>
        <joint name="arm_joint_01">
            <hardwareInterface>hardware_interface/EffortJointInterface</hardwareInterface>
        </joint>
        <actuator name="arm_joint_01_motor">
            <hardwareInterface>hardware_interface/EffortJointInterface</hardwareInterface>
            <mechanicalReduction>1</mechanicalReduction>
        </actuator>
    </transmission>
    <transmission name="trans_arm_joint_02">
        <type>transmission_interface/SimpleTransmission</type>
        <joint name="arm_joint_02">
            <hardwareInterface>hardware_interface/EffortJointInterface</hardwareInterface>
        </joint>
        <actuator name="arm_joint_02_motor">
            <hardwareInterface>hardware_interface/EffortJointInterface</hardwareInterface>
            <mechanicalReduction>1</mechanicalReduction>
        </actuator>
    </transmission>
    <transmission name="trans_arm_joint_03">
        <type>transmission_interface/SimpleTransmission</type>
        <joint name="arm_joint_03">
            <hardwareInterface>hardware_interface/EffortJointInterface</hardwareInterface>
        </joint>
        <actuator name="arm_joint_03_motor">
            <hardwareInterface>hardware_interface/EffortJointInterface</hardwareInterface>
            <mechanicalReduction>1</mechanicalReduction>
        </actuator>
    </transmission>
    <transmission name="trans_arm_joint_04">
        <type>transmission_interface/SimpleTransmission</type>
        <joint name="arm_joint_04">
            <hardwareInterface>hardware_interface/EffortJointInterface</hardwareInterface>
        </joint>
        <actuator name="arm_joint_04_motor">
            <hardwareInterface>hardware_interface/EffortJointInterface</hardwareInterface>
            <mechanicalReduction>1</mechanicalReduction>
        </actuator>
    </transmission>
    <transmission name="trans_cluedo_joint">
        <type>transmission_interface/SimpleTransmission</type>
        <joint name="cluedo_joint">
            <hardwareInterface>hardware_interface/EffortJointInterface</hardwareInterface>
        </joint>
        <actuator name="cluedo_joint_motor">
            <hardwareInterface>hardware_interface/EffortJointInterface</hardwareInterface>
            <mechanicalReduction>1</mechanicalReduction>
        </actuator>
    </transmission>
    <gazebo>
        <plugin name="gazebo_ros_control" filename="libgazebo_ros_control.so">
            <robotNamespace>/</robotNamespace>
        </plugin>
    </gazebo>
</robot>